### h1

3秒後にA, 2秒後にB, 1秒後にCが出力される。

理由: wait3(), wait2(), wait1() はそれぞれ非同期処理を行うが、awaitによって順番に実行される。各wait関数後に logA(), logB(), logC() が同じ順序で呼び出されるため、3秒後にA、その2秒後にB、その1秒後にCが順番に出力される。

### h2

Xのエラーメッセージが表示される。

理由: errX()の呼び出しで発生したエラーは Promiseのrejectとして扱われる。  
そのため、.catch ハンドラーでエラーがキャッチされ、log(e.message) が実行される。

### h3

エラーXが発生し、プログラムが終了する。

理由: async関数は常にPromiseを返すため、errX() による例外は単に無視され、.catch() には到達しない。

### h4

エラーYが発生し、プログラムが終了する。
(ブラウザだとエラーの後にxが出力される)

どちらの例外もキャッチできない

理由: p1が解決する前にp2がエラーをスローしてしまうため。その場合エラーはcatchブロックに到達せずに、関数の外で未処理のエラーとして現れてしまう。
